

<mujoco model="go2">
  <compiler angle="radian" meshdir="assets" autolimits="true" />

  <option cone="elliptic" impratio="100" timestep="0.001" />

  <default>

    <default class="go2">
      <geom friction="0.4" margin="0.001" condim="1"/>
      <joint axis="0 1 0" damping="0.1" armature="0.01" frictionloss="0.2"/>
      <motor ctrlrange="-23.7 23.7"/>

      <!-- 外展 -->
      <default class="abduction">
        <joint axis="1 0 0" range="-1.0472 1.0472"/>
      </default>

      <!-- 大腿关节 -->
      <default class="hip">
      <!-- 前大腿 -->
        <default class="front_hip">
          <joint range="-1.5708 3.4907"/>
        </default>
        <!-- 后大腿 -->
        <default class="back_hip">
          <joint range="-0.5236 4.5379"/>
        </default>
      </default>

      <!-- 小腿关节的 -->
      <default class="knee">
      <!-- <joint range="-2.7227 2"/>  -->
        <joint range="-2.7227 -0.83776"/> 
        <motor ctrlrange="-45.43 45.43"/>
      </default>
    
      <default class="visual">
        <geom type="mesh" contype="0" conaffinity="0" group="2" rgba="1 1 1 1" />
      </default>
      <!-- 碰撞 -->
      <default class="collision">
        <geom group="3"/>
        <default class="foot">
          <geom size="0.022" pos="-0.002 0 -0.213" priority="1" condim="6"
            friction="0.4 0.02 0.01"/>
        </default>
      </default>
    </default>
  </default>

  <asset>
    <material name="metal" rgba=".9 .95 .95 1" />
    <material name="black" rgba="0 0 0 1" />
    <material name="white" rgba="1 1 1 1" />
    <material name="gray" rgba="0.671705 0.692426 0.774270 1" />

    <mesh file="base_0.obj" />
    <mesh file="base_1.obj" />
    <mesh file="base_2.obj" />
    <mesh file="base_3.obj" />
    <mesh file="base_4.obj" />
    <mesh file="hip_0.obj" />
    <mesh file="hip_1.obj" />
    <mesh file="thigh_0.obj" />
    <mesh file="thigh_1.obj" />
    <mesh file="thigh_mirror_0.obj" />
    <mesh file="thigh_mirror_1.obj" />
    <mesh file="calf_0.obj" />
    <mesh file="calf_1.obj" />
    <mesh file="calf_mirror_0.obj" />
    <mesh file="calf_mirror_1.obj" />
    <mesh file="foot.obj" />
  </asset>

  <worldbody>
    <body name="base_link" pos="0 0 0.445" childclass="go2">
    <camera name="camera1" pos="0.33 0 0"  resolution="160 120" euler="0 -1.57 -1.57" />
      <inertial pos="0.021112 0 -0.005366" quat="-0.000543471 0.713435 -0.00173769 0.700719"
        mass="6.921"
        diaginertia="0.107027 0.0980771 0.0244531" />
      <freejoint />
      <geom mesh="base_0" material="black" class="visual" />
      <geom mesh="base_1" material="black" class="visual" />
      <geom mesh="base_2" material="black" class="visual" />
      <geom mesh="base_3" material="white" class="visual" />
      <geom mesh="base_4" material="gray" class="visual" />
      <geom size="0.1881 0.04675 0.057" type="box" class="collision" />
      <geom size="0.05 0.045" pos="0.285 0 0.01" type="cylinder" class="collision" />
      <geom size="0.047" pos="0.293 0 -0.06" class="collision" />
      <!-- <geom size="0.47" pos="0.293 0 -0.06" class="collision" /> -->

   <site name="imu" pos="-0.02557 0 0.04232" />
      <site name="lidar_site_000" pos="0.14 0 0.12" size="0.003" zaxis="1.000000 0.000000 0" rgba="0 1 0 0.15" />
      <site name="lidar_site_001" pos="0.14 0 0.12" size="0.003" zaxis="0.997564 0.069756 0" rgba="0 1 0 0.15" />
      <site name="lidar_site_002" pos="0.14 0 0.12" size="0.003" zaxis="0.990268 0.139173 0" rgba="0 1 0 0.15" />
      <site name="lidar_site_003" pos="0.14 0 0.12" size="0.003" zaxis="0.978148 0.207912 0" rgba="0 1 0 0.15" />
      <site name="lidar_site_004" pos="0.14 0 0.12" size="0.003" zaxis="0.961262 0.275637 0" rgba="0 1 0 0.15" />
      <site name="lidar_site_005" pos="0.14 0 0.12" size="0.003" zaxis="0.939693 0.342020 0" rgba="0 1 0 0.15" />
      <site name="lidar_site_006" pos="0.14 0 0.12" size="0.003" zaxis="0.913545 0.406737 0" rgba="0 1 0 0.15" />
      <site name="lidar_site_007" pos="0.14 0 0.12" size="0.003" zaxis="0.882948 0.469472 0" rgba="0 1 0 0.15" />
      <site name="lidar_site_008" pos="0.14 0 0.12" size="0.003" zaxis="0.848048 0.529919 0" rgba="0 1 0 0.15" />
      <site name="lidar_site_009" pos="0.14 0 0.12" size="0.003" zaxis="0.809017 0.587785 0" rgba="0 1 0 0.15" />
      <site name="lidar_site_010" pos="0.14 0 0.12" size="0.003" zaxis="0.766044 0.642788 0" rgba="0 1 0 0.15" />
      <site name="lidar_site_011" pos="0.14 0 0.12" size="0.003" zaxis="0.719340 0.694658 0" rgba="0 1 0 0.15" />
      <site name="lidar_site_012" pos="0.14 0 0.12" size="0.003" zaxis="0.669131 0.743145 0" rgba="0 1 0 0.15" />
      <site name="lidar_site_013" pos="0.14 0 0.12" size="0.003" zaxis="0.615661 0.788011 0" rgba="0 1 0 0.15" />
      <site name="lidar_site_014" pos="0.14 0 0.12" size="0.003" zaxis="0.559193 0.829038 0" rgba="0 1 0 0.15" />
      <site name="lidar_site_015" pos="0.14 0 0.12" size="0.003" zaxis="0.500000 0.866025 0" rgba="0 1 0 0.15" />
      <site name="lidar_site_016" pos="0.14 0 0.12" size="0.003" zaxis="0.438371 0.898794 0" rgba="0 1 0 0.15" />
      <site name="lidar_site_017" pos="0.14 0 0.12" size="0.003" zaxis="0.374607 0.927184 0" rgba="0 1 0 0.15" />
      <site name="lidar_site_018" pos="0.14 0 0.12" size="0.003" zaxis="0.309017 0.951057 0" rgba="0 1 0 0.15" />
      <site name="lidar_site_019" pos="0.14 0 0.12" size="0.003" zaxis="0.241922 0.970296 0" rgba="0 1 0 0.15" />
      <site name="lidar_site_020" pos="0.14 0 0.12" size="0.003" zaxis="0.173648 0.984808 0" rgba="0 1 0 0.15" />
      <site name="lidar_site_021" pos="0.14 0 0.12" size="0.003" zaxis="0.104528 0.994522 0" rgba="0 1 0 0.15" />
      <site name="lidar_site_022" pos="0.14 0 0.12" size="0.003" zaxis="0.034899 0.999391 0" rgba="0 1 0 0.15" />
      <site name="lidar_site_023" pos="0.14 0 0.12" size="0.003" zaxis="-0.034899 0.999391 0" rgba="0 1 0 0.15" />
      <site name="lidar_site_024" pos="0.14 0 0.12" size="0.003" zaxis="-0.104528 0.994522 0" rgba="0 1 0 0.15" />
      <site name="lidar_site_025" pos="0.14 0 0.12" size="0.003" zaxis="-0.173648 0.984808 0" rgba="0 1 0 0.15" />
      <site name="lidar_site_026" pos="0.14 0 0.12" size="0.003" zaxis="-0.241922 0.970296 0" rgba="0 1 0 0.15" />
      <site name="lidar_site_027" pos="0.14 0 0.12" size="0.003" zaxis="-0.309017 0.951057 0" rgba="0 1 0 0.15" />
      <site name="lidar_site_028" pos="0.14 0 0.12" size="0.003" zaxis="-0.374607 0.927184 0" rgba="0 1 0 0.15" />
      <site name="lidar_site_029" pos="0.14 0 0.12" size="0.003" zaxis="-0.438371 0.898794 0" rgba="0 1 0 0.15" />
      <site name="lidar_site_030" pos="0.14 0 0.12" size="0.003" zaxis="-0.500000 0.866025 0" rgba="0 1 0 0.15" />
      <site name="lidar_site_031" pos="0.14 0 0.12" size="0.003" zaxis="-0.559193 0.829038 0" rgba="0 1 0 0.15" />
      <site name="lidar_site_032" pos="0.14 0 0.12" size="0.003" zaxis="-0.615661 0.788011 0" rgba="0 1 0 0.15" />
      <site name="lidar_site_033" pos="0.14 0 0.12" size="0.003" zaxis="-0.669131 0.743145 0" rgba="0 1 0 0.15" />
      <site name="lidar_site_034" pos="0.14 0 0.12" size="0.003" zaxis="-0.719340 0.694658 0" rgba="0 1 0 0.15" />
      <site name="lidar_site_035" pos="0.14 0 0.12" size="0.003" zaxis="-0.766044 0.642788 0" rgba="0 1 0 0.15" />
      <site name="lidar_site_036" pos="0.14 0 0.12" size="0.003" zaxis="-0.809017 0.587785 0" rgba="0 1 0 0.15" />
      <site name="lidar_site_037" pos="0.14 0 0.12" size="0.003" zaxis="-0.848048 0.529919 0" rgba="0 1 0 0.15" />
      <site name="lidar_site_038" pos="0.14 0 0.12" size="0.003" zaxis="-0.882948 0.469472 0" rgba="0 1 0 0.15" />
      <site name="lidar_site_039" pos="0.14 0 0.12" size="0.003" zaxis="-0.913545 0.406737 0" rgba="0 1 0 0.15" />
      <site name="lidar_site_040" pos="0.14 0 0.12" size="0.003" zaxis="-0.939693 0.342020 0" rgba="0 1 0 0.15" />
      <site name="lidar_site_041" pos="0.14 0 0.12" size="0.003" zaxis="-0.961262 0.275637 0" rgba="0 1 0 0.15" />
      <site name="lidar_site_042" pos="0.14 0 0.12" size="0.003" zaxis="-0.978148 0.207912 0" rgba="0 1 0 0.15" />
      <site name="lidar_site_043" pos="0.14 0 0.12" size="0.003" zaxis="-0.990268 0.139173 0" rgba="0 1 0 0.15" />
      <site name="lidar_site_044" pos="0.14 0 0.12" size="0.003" zaxis="-0.997564 0.069756 0" rgba="0 1 0 0.15" />
      <site name="lidar_site_045" pos="0.14 0 0.12" size="0.003" zaxis="-1.000000 0.000000 0" rgba="0 1 0 0.15" />
      <site name="lidar_site_046" pos="0.14 0 0.12" size="0.003" zaxis="-0.997564 -0.069756 0" rgba="0 1 0 0.15" />
      <site name="lidar_site_047" pos="0.14 0 0.12" size="0.003" zaxis="-0.990268 -0.139173 0" rgba="0 1 0 0.15" />
      <site name="lidar_site_048" pos="0.14 0 0.12" size="0.003" zaxis="-0.978148 -0.207912 0" rgba="0 1 0 0.15" />
      <site name="lidar_site_049" pos="0.14 0 0.12" size="0.003" zaxis="-0.961262 -0.275637 0" rgba="0 1 0 0.15" />
      <site name="lidar_site_050" pos="0.14 0 0.12" size="0.003" zaxis="-0.939693 -0.342020 0" rgba="0 1 0 0.15" />
      <site name="lidar_site_051" pos="0.14 0 0.12" size="0.003" zaxis="-0.913545 -0.406737 0" rgba="0 1 0 0.15" />
      <site name="lidar_site_052" pos="0.14 0 0.12" size="0.003" zaxis="-0.882948 -0.469472 0" rgba="0 1 0 0.15" />
      <site name="lidar_site_053" pos="0.14 0 0.12" size="0.003" zaxis="-0.848048 -0.529919 0" rgba="0 1 0 0.15" />
      <site name="lidar_site_054" pos="0.14 0 0.12" size="0.003" zaxis="-0.809017 -0.587785 0" rgba="0 1 0 0.15" />
      <site name="lidar_site_055" pos="0.14 0 0.12" size="0.003" zaxis="-0.766044 -0.642788 0" rgba="0 1 0 0.15" />
      <site name="lidar_site_056" pos="0.14 0 0.12" size="0.003" zaxis="-0.719340 -0.694658 0" rgba="0 1 0 0.15" />
      <site name="lidar_site_057" pos="0.14 0 0.12" size="0.003" zaxis="-0.669131 -0.743145 0" rgba="0 1 0 0.15" />
      <site name="lidar_site_058" pos="0.14 0 0.12" size="0.003" zaxis="-0.615661 -0.788011 0" rgba="0 1 0 0.15" />
      <site name="lidar_site_059" pos="0.14 0 0.12" size="0.003" zaxis="-0.559193 -0.829038 0" rgba="0 1 0 0.15" />
      <site name="lidar_site_060" pos="0.14 0 0.12" size="0.003" zaxis="-0.500000 -0.866025 0" rgba="0 1 0 0.15" />
      <site name="lidar_site_061" pos="0.14 0 0.12" size="0.003" zaxis="-0.438371 -0.898794 0" rgba="0 1 0 0.15" />
      <site name="lidar_site_062" pos="0.14 0 0.12" size="0.003" zaxis="-0.374607 -0.927184 0" rgba="0 1 0 0.15" />
      <site name="lidar_site_063" pos="0.14 0 0.12" size="0.003" zaxis="-0.309017 -0.951057 0" rgba="0 1 0 0.15" />
      <site name="lidar_site_064" pos="0.14 0 0.12" size="0.003" zaxis="-0.241922 -0.970296 0" rgba="0 1 0 0.15" />
      <site name="lidar_site_065" pos="0.14 0 0.12" size="0.003" zaxis="-0.173648 -0.984808 0" rgba="0 1 0 0.15" />
      <site name="lidar_site_066" pos="0.14 0 0.12" size="0.003" zaxis="-0.104528 -0.994522 0" rgba="0 1 0 0.15" />
      <site name="lidar_site_067" pos="0.14 0 0.12" size="0.003" zaxis="-0.034899 -0.999391 0" rgba="0 1 0 0.15" />
      <site name="lidar_site_068" pos="0.14 0 0.12" size="0.003" zaxis="0.034899 -0.999391 0" rgba="0 1 0 0.15" />
      <site name="lidar_site_069" pos="0.14 0 0.12" size="0.003" zaxis="0.104528 -0.994522 0" rgba="0 1 0 0.15" />
      <site name="lidar_site_070" pos="0.14 0 0.12" size="0.003" zaxis="0.173648 -0.984808 0" rgba="0 1 0 0.15" />
      <site name="lidar_site_071" pos="0.14 0 0.12" size="0.003" zaxis="0.241922 -0.970296 0" rgba="0 1 0 0.15" />
      <site name="lidar_site_072" pos="0.14 0 0.12" size="0.003" zaxis="0.309017 -0.951057 0" rgba="0 1 0 0.15" />
      <site name="lidar_site_073" pos="0.14 0 0.12" size="0.003" zaxis="0.374607 -0.927184 0" rgba="0 1 0 0.15" />
      <site name="lidar_site_074" pos="0.14 0 0.12" size="0.003" zaxis="0.438371 -0.898794 0" rgba="0 1 0 0.15" />
      <site name="lidar_site_075" pos="0.14 0 0.12" size="0.003" zaxis="0.500000 -0.866025 0" rgba="0 1 0 0.15" />
      <site name="lidar_site_076" pos="0.14 0 0.12" size="0.003" zaxis="0.559193 -0.829038 0" rgba="0 1 0 0.15" />
      <site name="lidar_site_077" pos="0.14 0 0.12" size="0.003" zaxis="0.615661 -0.788011 0" rgba="0 1 0 0.15" />
      <site name="lidar_site_078" pos="0.14 0 0.12" size="0.003" zaxis="0.669131 -0.743145 0" rgba="0 1 0 0.15" />
      <site name="lidar_site_079" pos="0.14 0 0.12" size="0.003" zaxis="0.719340 -0.694658 0" rgba="0 1 0 0.15" />
      <site name="lidar_site_080" pos="0.14 0 0.12" size="0.003" zaxis="0.766044 -0.642788 0" rgba="0 1 0 0.15" />
      <site name="lidar_site_081" pos="0.14 0 0.12" size="0.003" zaxis="0.809017 -0.587785 0" rgba="0 1 0 0.15" />
      <site name="lidar_site_082" pos="0.14 0 0.12" size="0.003" zaxis="0.848048 -0.529919 0" rgba="0 1 0 0.15" />
      <site name="lidar_site_083" pos="0.14 0 0.12" size="0.003" zaxis="0.882948 -0.469472 0" rgba="0 1 0 0.15" />
      <site name="lidar_site_084" pos="0.14 0 0.12" size="0.003" zaxis="0.913545 -0.406737 0" rgba="0 1 0 0.15" />
      <site name="lidar_site_085" pos="0.14 0 0.12" size="0.003" zaxis="0.939693 -0.342020 0" rgba="0 1 0 0.15" />
      <site name="lidar_site_086" pos="0.14 0 0.12" size="0.003" zaxis="0.961262 -0.275637 0" rgba="0 1 0 0.15" />
      <site name="lidar_site_087" pos="0.14 0 0.12" size="0.003" zaxis="0.978148 -0.207912 0" rgba="0 1 0 0.15" />
      <site name="lidar_site_088" pos="0.14 0 0.12" size="0.003" zaxis="0.990268 -0.139173 0" rgba="0 1 0 0.15" />
      <site name="lidar_site_089" pos="0.14 0 0.12" size="0.003" zaxis="0.997564 -0.069756 0" rgba="0 1 0 0.15" />
      <!-- 前左 -->
      <body name="FL_hip" pos="0.1934 0.0465 0">
        <inertial pos="-0.0054 0.00194 -0.000105" quat="0.497014 0.499245 0.505462 0.498237"
          mass="0.678"
          diaginertia="0.00088403 0.000596003 0.000479967" />
        <joint name="FL_hip_joint" class="abduction" />
        <geom mesh="hip_0" material="metal" class="visual" />
        <geom mesh="hip_1" material="gray" class="visual" />
        <geom size="0.046 0.02" pos="0 0.08 0" quat="1 1 0 0" type="cylinder" class="collision" />
        <body name="FL_thigh" pos="0 0.0955 0">
          <inertial pos="-0.00374 -0.0223 -0.0327" quat="0.829533 0.0847635 -0.0200632 0.551623"
            mass="1.152"
            diaginertia="0.00594973 0.00584149 0.000878787" />
          <joint name="FL_thigh_joint" class="front_hip" />
          <geom mesh="thigh_0" material="metal" class="visual" />
          <geom mesh="thigh_1" material="gray" class="visual" />
          <geom size="0.1065 0.01225 0.017" pos="0 0 -0.1065" quat="0.707107 0 0.707107 0"
            type="box" class="collision" />
          <body name="FL_calf" pos="0 0 -0.213">
            <inertial pos="0.00629595 -0.000622121 -0.141417"
              quat="0.710672 0.00154099 -0.00450087 0.703508"
              mass="0.241352" diaginertia="0.0014901 0.00146356 5.31397e-05" />
            <joint name="FL_calf_joint" class="knee" />
            <geom mesh="calf_0" material="gray" class="visual" />
            <geom mesh="calf_1" material="black" class="visual" />
            <geom size="0.012 0.06" pos="0.008 0 -0.06" quat="0.994493 0 -0.104807 0"
              type="cylinder" class="collision" />
            <geom size="0.011 0.0325" pos="0.02 0 -0.148" quat="0.999688 0 0.0249974 0"
              type="cylinder" class="collision" />
            <geom pos="0 0 -0.213" mesh="foot" class="visual" material="black" />
            <geom name="FL" class="foot" />
            <body name="FL_foot" pos="0 0 -0.213" />
          </body>
        </body>
      </body>
      <!-- 前右 -->
      <body name="FR_hip" pos="0.1934 -0.0465 0">
        <inertial pos="-0.0054 -0.00194 -0.000105" quat="0.498237 0.505462 0.499245 0.497014"
          mass="0.678"
          diaginertia="0.00088403 0.000596003 0.000479967" />
        <joint name="FR_hip_joint" class="abduction" />
        <geom mesh="hip_0" material="metal" class="visual" quat="4.63268e-05 1 0 0" />
        <geom mesh="hip_1" material="gray" class="visual" quat="4.63268e-05 1 0 0" />
        <geom size="0.046 0.02" pos="0 -0.08 0" quat="0.707107 0.707107 0 0" type="cylinder"
          class="collision" />
        <body name="FR_thigh" pos="0 -0.0955 0">
          <inertial pos="-0.00374 0.0223 -0.0327" quat="0.551623 -0.0200632 0.0847635 0.829533"
            mass="1.152"
            diaginertia="0.00594973 0.00584149 0.000878787" />
          <joint name="FR_thigh_joint" class="front_hip" />
          <geom mesh="thigh_mirror_0" material="metal" class="visual" />
          <geom mesh="thigh_mirror_1" material="gray" class="visual" />
          <geom size="0.1065 0.01225 0.017" pos="0 0 -0.1065" quat="0.707107 0 0.707107 0"
            type="box" class="collision" />
          <body name="FR_calf" pos="0 0 -0.213">
            <inertial pos="0.00629595 0.000622121 -0.141417"
              quat="0.703508 -0.00450087 0.00154099 0.710672"
              mass="0.241352" diaginertia="0.0014901 0.00146356 5.31397e-05" />
            <joint name="FR_calf_joint" class="knee" />
            <geom mesh="calf_mirror_0" material="gray" class="visual" />
            <geom mesh="calf_mirror_1" material="black" class="visual" />
            <geom size="0.013 0.06" pos="0.01 0 -0.06" quat="0.995004 0 -0.0998334 0"
              type="cylinder" class="collision" />
            <geom size="0.011 0.0325" pos="0.02 0 -0.148" quat="0.999688 0 0.0249974 0"
              type="cylinder" class="collision" />
            <geom pos="0 0 -0.213" mesh="foot" class="visual" material="black" />
            <geom name="FR" class="foot" />
            <body name="FR_foot" pos="0 0 -0.213" />
          </body>
        </body>
      </body>
      <!-- 后左 -->
      <body name="RL_hip" pos="-0.1934 0.0465 0">
        <inertial pos="0.0054 0.00194 -0.000105" quat="0.505462 0.498237 0.497014 0.499245"
          mass="0.678"
          diaginertia="0.00088403 0.000596003 0.000479967" />
        <joint name="RL_hip_joint" class="abduction" />
        <geom mesh="hip_0" material="metal" class="visual" quat="4.63268e-05 0 1 0" />
        <geom mesh="hip_1" material="gray" class="visual" quat="4.63268e-05 0 1 0" />
        <geom size="0.046 0.02" pos="0 0.08 0" quat="0.707107 0.707107 0 0" type="cylinder"
          class="collision" />
        <body name="RL_thigh" pos="0 0.0955 0">
          <inertial pos="-0.00374 -0.0223 -0.0327" quat="0.829533 0.0847635 -0.0200632 0.551623"
            mass="1.152"
            diaginertia="0.00594973 0.00584149 0.000878787" />
          <joint name="RL_thigh_joint" class="back_hip" />
          <geom mesh="thigh_0" material="metal" class="visual" />
          <geom mesh="thigh_1" material="gray" class="visual" />
          <geom size="0.1065 0.01225 0.017" pos="0 0 -0.1065" quat="0.707107 0 0.707107 0"
            type="box" class="collision" />
          <body name="RL_calf" pos="0 0 -0.213">
            <inertial pos="0.00629595 -0.000622121 -0.141417"
              quat="0.710672 0.00154099 -0.00450087 0.703508"
              mass="0.241352" diaginertia="0.0014901 0.00146356 5.31397e-05" />
            <joint name="RL_calf_joint" class="knee" />
            <geom mesh="calf_0" material="gray" class="visual" />
            <geom mesh="calf_1" material="black" class="visual" />
            <geom size="0.013 0.06" pos="0.01 0 -0.06" quat="0.995004 0 -0.0998334 0"
              type="cylinder" class="collision" />
            <geom size="0.011 0.0325" pos="0.02 0 -0.148" quat="0.999688 0 0.0249974 0"
              type="cylinder" class="collision" />
            <geom pos="0 0 -0.213" mesh="foot" class="visual" material="black" />
            <geom name="RL" class="foot" />
            <body name="RL_foot" pos="0 0 -0.213" />
          </body>
        </body>
      </body>
      <!-- 后右边 -->
      <body name="RR_hip" pos="-0.1934 -0.0465 0">
        <inertial pos="0.0054 -0.00194 -0.000105" quat="0.499245 0.497014 0.498237 0.505462"
          mass="0.678"
          diaginertia="0.00088403 0.000596003 0.000479967" />
        <joint name="RR_hip_joint" class="abduction" />
        <geom mesh="hip_0" material="metal" class="visual"
          quat="2.14617e-09 4.63268e-05 4.63268e-05 -1" />
        <geom mesh="hip_1" material="gray" class="visual"
          quat="2.14617e-09 4.63268e-05 4.63268e-05 -1" />
        <geom size="0.046 0.02" pos="0 -0.08 0" quat="0.707107 0.707107 0 0" type="cylinder"
          class="collision" />
        <body name="RR_thigh" pos="0 -0.0955 0">
          <inertial pos="-0.00374 0.0223 -0.0327" quat="0.551623 -0.0200632 0.0847635 0.829533"
            mass="1.152"
            diaginertia="0.00594973 0.00584149 0.000878787" />
          <joint name="RR_thigh_joint" class="back_hip" />
          <geom mesh="thigh_mirror_0" material="metal" class="visual" />
          <geom mesh="thigh_mirror_1" material="gray" class="visual" />
          <geom size="0.1065 0.01225 0.017" pos="0 0 -0.1065" quat="0.707107 0 0.707107 0"
            type="box" class="collision" />
          <body name="RR_calf" pos="0 0 -0.213">
            <inertial pos="0.00629595 0.000622121 -0.141417"
              quat="0.703508 -0.00450087 0.00154099 0.710672"
              mass="0.241352" diaginertia="0.0014901 0.00146356 5.31397e-05" />
            <joint name="RR_calf_joint" class="knee" />
            <geom mesh="calf_mirror_0" material="gray" class="visual" />
            <geom mesh="calf_mirror_1" material="black" class="visual" />
            <geom size="0.013 0.06" pos="0.01 0 -0.06" quat="0.995004 0 -0.0998334 0"
              type="cylinder" class="collision" />
            <geom size="0.011 0.0325" pos="0.02 0 -0.148" quat="0.999688 0 0.0249974 0"
              type="cylinder" class="collision" />
            <geom pos="0 0 -0.213" mesh="foot" class="visual" material="black" />
            <geom name="RR" class="foot" />
            <body name="RR_foot" pos="0 0 -0.213" />
          </body>
        </body>
      </body>
    </body>
  </worldbody>


<!-- 控制器 -->
  <actuator>
    <motor class="abduction" name="FR_hip" joint="FR_hip_joint"  />
    <motor class="hip" name="FR_thigh" joint="FR_thigh_joint"   />
    <motor class="knee" name="FR_calf" joint="FR_calf_joint"  />
    <motor class="abduction" name="FL_hip" joint="FL_hip_joint"  />
    <motor class="hip" name="FL_thigh" joint="FL_thigh_joint"  />
    <motor class="knee" name="FL_calf" joint="FL_calf_joint"  />
    <motor class="abduction" name="RR_hip" joint="RR_hip_joint"  />
    <motor class="hip" name="RR_thigh" joint="RR_thigh_joint"  />
    <motor class="knee" name="RR_calf" joint="RR_calf_joint"  />
    <motor class="abduction" name="RL_hip" joint="RL_hip_joint"  />
    <motor class="hip" name="RL_thigh" joint="RL_thigh_joint"  />
    <motor class="knee" name="RL_calf" joint="RL_calf_joint" />
    <!-- <position class="abduction" name="FR_hip" joint="FR_hip_joint" kp="100" kv="1" />
    <position class="hip" name="FR_thigh" joint="FR_thigh_joint"   kp="100" kv="1"/>
    <position class="knee" name="FR_calf" joint="FR_calf_joint"  kp="100" kv="1"/>
    <position class="abduction" name="FL_hip" joint="FL_hip_joint"  kp="100" kv="1"/>
    <position class="hip" name="FL_thigh" joint="FL_thigh_joint"  kp="100" kv="1"/>
    <position class="knee" name="FL_calf" joint="FL_calf_joint"  kp="100" kv="1"/>
    <position class="abduction" name="RR_hip" joint="RR_hip_joint" kp="100" kv="1" />
    <position class="hip" name="RR_thigh" joint="RR_thigh_joint"  kp="100" kv="1"/>
    <position class="knee" name="RR_calf" joint="RR_calf_joint"  kp="100" kv="1"/>
    <position class="abduction" name="RL_hip" joint="RL_hip_joint"  kp="100" kv="1"/>
    <position class="hip" name="RL_thigh" joint="RL_thigh_joint"  kp="100" kv="1"/>
    <position class="knee" name="RL_calf" joint="RL_calf_joint"  kp="100" kv="1"/> -->
  </actuator>

  <sensor>
    <jointpos name="FR_hip_pos" joint="FR_hip_joint" />
    <jointpos name="FR_thigh_pos" joint="FR_thigh_joint" />
    <jointpos name="FR_calf_pos" joint="FR_calf_joint" />
    <jointpos name="FL_hip_pos" joint="FL_hip_joint" />
    <jointpos name="FL_thigh_pos" joint="FL_thigh_joint" />
    <jointpos name="FL_calf_pos" joint="FL_calf_joint" />
    <jointpos name="RR_hip_pos" joint="RR_hip_joint" />
    <jointpos name="RR_thigh_pos" joint="RR_thigh_joint" />
    <jointpos name="RR_calf_pos" joint="RR_calf_joint" />
    <jointpos name="RL_hip_pos" joint="RL_hip_joint" />
    <jointpos name="RL_thigh_pos" joint="RL_thigh_joint" />
    <jointpos name="RL_calf_pos" joint="RL_calf_joint" />

    <jointvel name="FR_hip_vel" joint="FR_hip_joint" />
    <jointvel name="FR_thigh_vel" joint="FR_thigh_joint" />
    <jointvel name="FR_calf_vel" joint="FR_calf_joint" />
    <jointvel name="FL_hip_vel" joint="FL_hip_joint" />
    <jointvel name="FL_thigh_vel" joint="FL_thigh_joint" />
    <jointvel name="FL_calf_vel" joint="FL_calf_joint" />
    <jointvel name="RR_hip_vel" joint="RR_hip_joint" />
    <jointvel name="RR_thigh_vel" joint="RR_thigh_joint" />
    <jointvel name="RR_calf_vel" joint="RR_calf_joint" />
    <jointvel name="RL_hip_vel" joint="RL_hip_joint" />
    <jointvel name="RL_thigh_vel" joint="RL_thigh_joint" />
    <jointvel name="RL_calf_vel" joint="RL_calf_joint" />

    <jointactuatorfrc name="FR_hip_torque" joint="FR_hip_joint" noise="0.01" />
    <jointactuatorfrc name="FR_thigh_torque" joint="FR_thigh_joint" noise="0.01" />
    <jointactuatorfrc name="FR_calf_torque" joint="FR_calf_joint" noise="0.01" />
    <jointactuatorfrc name="FL_hip_torque" joint="FL_hip_joint" noise="0.01" />
    <jointactuatorfrc name="FL_thigh_torque" joint="FL_thigh_joint" noise="0.01" />
    <jointactuatorfrc name="FL_calf_torque" joint="FL_calf_joint" noise="0.01" />
    <jointactuatorfrc name="RR_hip_torque" joint="RR_hip_joint" noise="0.01" />
    <jointactuatorfrc name="RR_thigh_torque" joint="RR_thigh_joint" noise="0.01" />
    <jointactuatorfrc name="RR_calf_torque" joint="RR_calf_joint" noise="0.01" />
    <jointactuatorfrc name="RL_hip_torque" joint="RL_hip_joint" noise="0.01" />
    <jointactuatorfrc name="RL_thigh_torque" joint="RL_thigh_joint" noise="0.01" />
    <jointactuatorfrc name="RL_calf_torque" joint="RL_calf_joint" noise="0.01" />

    <!-- 输出四元数 -->
    <framequat name="imu_quat" objtype="site" objname="imu" />
    <!-- 线加速度 -->
    <accelerometer name="imu_acc" site="imu"  />
    <!-- 角速度 --> 
     <gyro name="imu_gyro" site="imu"  />
    <rangefinder name="lidar_000" site="lidar_site_000" />
    <rangefinder name="lidar_001" site="lidar_site_001" />
    <rangefinder name="lidar_002" site="lidar_site_002" />
    <rangefinder name="lidar_003" site="lidar_site_003" />
    <rangefinder name="lidar_004" site="lidar_site_004" />
    <rangefinder name="lidar_005" site="lidar_site_005" />
    <rangefinder name="lidar_006" site="lidar_site_006" />
    <rangefinder name="lidar_007" site="lidar_site_007" />
    <rangefinder name="lidar_008" site="lidar_site_008" />
    <rangefinder name="lidar_009" site="lidar_site_009" />
    <rangefinder name="lidar_010" site="lidar_site_010" />
    <rangefinder name="lidar_011" site="lidar_site_011" />
    <rangefinder name="lidar_012" site="lidar_site_012" />
    <rangefinder name="lidar_013" site="lidar_site_013" />
    <rangefinder name="lidar_014" site="lidar_site_014" />
    <rangefinder name="lidar_015" site="lidar_site_015" />
    <rangefinder name="lidar_016" site="lidar_site_016" />
    <rangefinder name="lidar_017" site="lidar_site_017" />
    <rangefinder name="lidar_018" site="lidar_site_018" />
    <rangefinder name="lidar_019" site="lidar_site_019" />
    <rangefinder name="lidar_020" site="lidar_site_020" />
    <rangefinder name="lidar_021" site="lidar_site_021" />
    <rangefinder name="lidar_022" site="lidar_site_022" />
    <rangefinder name="lidar_023" site="lidar_site_023" />
    <rangefinder name="lidar_024" site="lidar_site_024" />
    <rangefinder name="lidar_025" site="lidar_site_025" />
    <rangefinder name="lidar_026" site="lidar_site_026" />
    <rangefinder name="lidar_027" site="lidar_site_027" />
    <rangefinder name="lidar_028" site="lidar_site_028" />
    <rangefinder name="lidar_029" site="lidar_site_029" />
    <rangefinder name="lidar_030" site="lidar_site_030" />
    <rangefinder name="lidar_031" site="lidar_site_031" />
    <rangefinder name="lidar_032" site="lidar_site_032" />
    <rangefinder name="lidar_033" site="lidar_site_033" />
    <rangefinder name="lidar_034" site="lidar_site_034" />
    <rangefinder name="lidar_035" site="lidar_site_035" />
    <rangefinder name="lidar_036" site="lidar_site_036" />
    <rangefinder name="lidar_037" site="lidar_site_037" />
    <rangefinder name="lidar_038" site="lidar_site_038" />
    <rangefinder name="lidar_039" site="lidar_site_039" />
    <rangefinder name="lidar_040" site="lidar_site_040" />
    <rangefinder name="lidar_041" site="lidar_site_041" />
    <rangefinder name="lidar_042" site="lidar_site_042" />
    <rangefinder name="lidar_043" site="lidar_site_043" />
    <rangefinder name="lidar_044" site="lidar_site_044" />
    <rangefinder name="lidar_045" site="lidar_site_045" />
    <rangefinder name="lidar_046" site="lidar_site_046" />
    <rangefinder name="lidar_047" site="lidar_site_047" />
    <rangefinder name="lidar_048" site="lidar_site_048" />
    <rangefinder name="lidar_049" site="lidar_site_049" />
    <rangefinder name="lidar_050" site="lidar_site_050" />
    <rangefinder name="lidar_051" site="lidar_site_051" />
    <rangefinder name="lidar_052" site="lidar_site_052" />
    <rangefinder name="lidar_053" site="lidar_site_053" />
    <rangefinder name="lidar_054" site="lidar_site_054" />
    <rangefinder name="lidar_055" site="lidar_site_055" />
    <rangefinder name="lidar_056" site="lidar_site_056" />
    <rangefinder name="lidar_057" site="lidar_site_057" />
    <rangefinder name="lidar_058" site="lidar_site_058" />
    <rangefinder name="lidar_059" site="lidar_site_059" />
    <rangefinder name="lidar_060" site="lidar_site_060" />
    <rangefinder name="lidar_061" site="lidar_site_061" />
    <rangefinder name="lidar_062" site="lidar_site_062" />
    <rangefinder name="lidar_063" site="lidar_site_063" />
    <rangefinder name="lidar_064" site="lidar_site_064" />
    <rangefinder name="lidar_065" site="lidar_site_065" />
    <rangefinder name="lidar_066" site="lidar_site_066" />
    <rangefinder name="lidar_067" site="lidar_site_067" />
    <rangefinder name="lidar_068" site="lidar_site_068" />
    <rangefinder name="lidar_069" site="lidar_site_069" />
    <rangefinder name="lidar_070" site="lidar_site_070" />
    <rangefinder name="lidar_071" site="lidar_site_071" />
    <rangefinder name="lidar_072" site="lidar_site_072" />
    <rangefinder name="lidar_073" site="lidar_site_073" />
    <rangefinder name="lidar_074" site="lidar_site_074" />
    <rangefinder name="lidar_075" site="lidar_site_075" />
    <rangefinder name="lidar_076" site="lidar_site_076" />
    <rangefinder name="lidar_077" site="lidar_site_077" />
    <rangefinder name="lidar_078" site="lidar_site_078" />
    <rangefinder name="lidar_079" site="lidar_site_079" />
    <rangefinder name="lidar_080" site="lidar_site_080" />
    <rangefinder name="lidar_081" site="lidar_site_081" />
    <rangefinder name="lidar_082" site="lidar_site_082" />
    <rangefinder name="lidar_083" site="lidar_site_083" />
    <rangefinder name="lidar_084" site="lidar_site_084" />
    <rangefinder name="lidar_085" site="lidar_site_085" />
    <rangefinder name="lidar_086" site="lidar_site_086" />
    <rangefinder name="lidar_087" site="lidar_site_087" />
    <rangefinder name="lidar_088" site="lidar_site_088" />
    <rangefinder name="lidar_089" site="lidar_site_089" />


    
    <!-- 位置 -->
    <!-- <framepos name="frame_pos" objtype="site" objname="imu" /> -->
    <!-- 线速度 -->
    <!-- <framelinvel name="frame_vel" objtype="site" objname="imu" /> -->
  </sensor>

  <keyframe>
    <key name="home" qpos="1 0 0.27 1 0 0 0 0 0.9 -1.8 0 0.9 -1.8 0 0.9 -1.8 0 0.9 -1.8"
      ctrl="0 0.9 -1.8 0 0.9 -1.8 0 0.9 -1.8 0 0.9 -1.8" />
  </keyframe>
</mujoco>





